Traceback (most recent call last):
  File "/state/partition1/llgrid/pkg/anaconda/python-ML-2025a/lib/python3.10/site-packages/pandas/core/indexes/base.py", line 3805, in get_loc
    return self._engine.get_loc(casted_key)
  File "index.pyx", line 167, in pandas._libs.index.IndexEngine.get_loc
  File "index.pyx", line 196, in pandas._libs.index.IndexEngine.get_loc
  File "pandas/_libs/hashtable_class_helper.pxi", line 7081, in pandas._libs.hashtable.PyObjectHashTable.get_item
  File "pandas/_libs/hashtable_class_helper.pxi", line 7089, in pandas._libs.hashtable.PyObjectHashTable.get_item
KeyError: 'error'

The above exception was the direct cause of the following exception:

Traceback (most recent call last):
  File "/state/partition1/llgrid/pkg/anaconda/python-ML-2025a/lib/python3.10/runpy.py", line 196, in _run_module_as_main
    return _run_code(code, main_globals, None,
  File "/state/partition1/llgrid/pkg/anaconda/python-ML-2025a/lib/python3.10/runpy.py", line 86, in _run_code
    exec(code, run_globals)
  File "/home/gridsan/mknuth/02_Full_Model/src/model/gnn_hyperparameter_tuning.py", line 706, in <module>
    main()
  File "/home/gridsan/mknuth/02_Full_Model/src/model/gnn_hyperparameter_tuning.py", line 672, in main
    summary_data = df_final[df_final["error"].isna()].copy()
  File "/state/partition1/llgrid/pkg/anaconda/python-ML-2025a/lib/python3.10/site-packages/pandas/core/frame.py", line 4102, in __getitem__
    indexer = self.columns.get_loc(key)
  File "/state/partition1/llgrid/pkg/anaconda/python-ML-2025a/lib/python3.10/site-packages/pandas/core/indexes/base.py", line 3812, in get_loc
    raise KeyError(key) from err
KeyError: 'error'
